DEBUG:matplotlib.font_manager:findfont: Matching :family=sans-serif:style=normal:variant=normal:weight=normal:stretch=normal:size=10.0 to DejaVu Sans ('C:\\ProgramData\\Anaconda\\lib\\site-packages\\matplotlib\\mpl-data\\fonts\\ttf\\DejaVuSans.ttf') with score of 0.050000
DEBUG:matplotlib.font_manager:findfont: Matching :family=sans-serif:style=normal:variant=normal:weight=normal:stretch=normal:size=30.0 to DejaVu Sans ('C:\\ProgramData\\Anaconda\\lib\\site-packages\\matplotlib\\mpl-data\\fonts\\ttf\\DejaVuSans.ttf') with score of 0.050000
DEBUG:matplotlib.font_manager:findfont: Matching :family=serif:style=normal:variant=normal:weight=normal:stretch=normal:size=10.0 to DejaVu Serif ('C:\\ProgramData\\Anaconda\\lib\\site-packages\\matplotlib\\mpl-data\\fonts\\ttf\\DejaVuSerif.ttf') with score of 0.050000
DEBUG:matplotlib.font_manager:findfont: Matching :family=serif:style=normal:variant=normal:weight=normal:stretch=normal:size=30.0 to DejaVu Serif ('C:\\ProgramData\\Anaconda\\lib\\site-packages\\matplotlib\\mpl-data\\fonts\\ttf\\DejaVuSerif.ttf') with score of 0.050000
CRITICAL:__main__:Unhandled exception
Traceback (most recent call last):
  File "C:\Users\seery\Documents\GitHub\Telemetry-Grapher\Telemetry-Grapher\classes\gt.py", line 111, in search_dir
    self.loaded_files, new_path_dict_entries = self.gather_files(path)
  File "C:\Users\seery\Documents\GitHub\Telemetry-Grapher\Telemetry-Grapher\classes\gt.py", line 133, in gather_files
    for file in os.listdir(path):
FileNotFoundError: [WinError 3] The system cannot find the path specified: 'C:\\Users\\seery\\Documents\\GitHub\\Telemetry-Grapher\\Telemetry-Grapher\\test'
DEBUG:matplotlib.font_manager:findfont: Matching :family=serif:style=normal:variant=normal:weight=normal:stretch=normal:size=12.0 to DejaVu Serif ('C:\\ProgramData\\Anaconda\\lib\\site-packages\\matplotlib\\mpl-data\\fonts\\ttf\\DejaVuSerif.ttf') with score of 0.050000
CRITICAL:__main__:Unhandled exception
Traceback (most recent call last):
  File "C:\Users\seery\Documents\GitHub\Telemetry-Grapher\Telemetry-Grapher\classes\dm.py", line 123, in save_changes
    del new_contents[new_name][new_alias]
KeyError: 'PHI_aPCM_I_HEATER []'
CRITICAL:__main__:Unhandled exception
Traceback (most recent call last):
  File "C:\Users\seery\Documents\GitHub\Telemetry-Grapher\Telemetry-Grapher\classes\dm.py", line 123, in save_changes
    del new_contents[new_name][new_alias]
KeyError: 'PHI_aPCM_I_MECH []'
CRITICAL:__main__:Unhandled exception
Traceback (most recent call last):
  File "C:\Users\seery\Documents\GitHub\Telemetry-Grapher\Telemetry-Grapher\classes\dm.py", line 123, in save_changes
    del new_contents[new_name][new_alias]
KeyError: 'PHI_aPCM_I_neg15V []'
CRITICAL:__main__:Unhandled exception
Traceback (most recent call last):
  File "C:\Users\seery\Documents\GitHub\Telemetry-Grapher\Telemetry-Grapher\classes\dm.py", line 123, in save_changes
    del new_contents[new_name][new_alias]
KeyError: 'PHI_aPCM_I_neg7V []'
CRITICAL:__main__:Unhandled exception
Traceback (most recent call last):
  File "C:\Users\seery\Documents\GitHub\Telemetry-Grapher\Telemetry-Grapher\classes\dm.py", line 123, in save_changes
    del new_contents[new_name][new_alias]
KeyError: 'PHI_aPCM_I_pos15V []'
